Workbook

Sheet economy
C3: NB! I have moved it one quarter to be real quarter since siemens af one quarter moved accounting
C5: 2022 | G5: 2021 | K5: 2020 | O5: 2019 | S5: 2018 | W5: 2017 | AA5: 2016
B6: q4 | C6: q3 | D6: q2 | E6: q1 | F6: q4 | G6: q3 | H6: q2 | I6: q1 | J6: q4 | K6: q3 | L6: q2 | M6: q1 | N6: q4 | O6: q3 | P6: q2 | Q6: q1 | R6: q4 | S6: q3 | T6: q2 | U6: q1 | V6: q4 | W6: q3 | X6: q2 | Y6: q1 | Z6: q4 | AA6: q3 | AB6: q2 | AC6: q1
A7: revenue | C7: 9814
A8: Net income | C8: -940
A9: Orderbook | C9: 35051
A10: firm order intake [M€] | C10: 4405
A11: order intake onshore [M€] | C11: 1743 | D11: 1068 | E11: 209 | F11: 1361 | G11: 867 | H11: 840 | I11: 1381 | J11: 1619
A12: order intake offshore [M€] | C12: 1566 | D12: 2094 | E12: 321 | F12: 416 | G12: 888 | H12: 146 | I12: 2877 | J12: 157
A13: order intake service [M€] | C13: 1097 | D13: 361 | E13: 669 | F13: 695 | G13: 1129 | H13: 534 | I13: 1242 | J13: 505
A14: order intake onshore [MW] | G14: 2223 | H14: 2404 | I14: 1927 | J14: 1744 | K14: 2433 | L14: 1876 | M14: 1649 | N14: 1747 | V14: 2167 | W14: 693 | X14: 1599 | Y14: 1882 | Z14: 2063 | AA14: 1662 | AB14: 1528 | AC14: 1781
A15: order intake offshore [MW] | G15: 558 | H15: 675 | I15: 730 | J15: 734 | K15: 793 | L15: 751 | M15: 534 | N15: 185 | V15: 366 | W15: 754 | X15: 948 | Y15: 28 | Z15: 294 | AA15: 574 | AB15: 112 | AC15: 752
B16: =B15+B14 -> 0 | C16: =C15+C14 -> 0 | D16: =D15+D14 -> 0 | E16: =E15+E14 -> 0 | F16: =F15+F14 -> 0 | G16: =G15+G14 -> 2781 | H16: =H15+H14 -> 3079 | I16: =I15+I14 -> 2657 | ... AC16: =AC15+AC14 -> 2533
A17: Fleet | C17: 127476
A18: under maintanance - total | V18: =V19+V20 -> 55173 | W18: =W19+W20 -> 53643 | X18: =X19+X20 -> 53358 | Y18: =Y19+Y20 -> 50734 | Z18: =Z19+Z20 -> 49098 | AA18: =AA19+AA20 -> 47598 | AB18: =AB19+AB20 -> 46902 | AC18: =AC19+AC20 -> 45123
A19: under maintanance -onshore | V19: 46629 | W19: 45976 | X19: 46111 | Y19: 43192 | Z19: 41748 | AA19: 41062 | AB19: 40844 | AC19: 39469
A20: under maintanance -offshore | C20: 82276 | V20: 8544 | W20: 7667 | X20: 7247 | Y20: 7542 | Z20: 7350 | AA20: 6536 | AB20: 6058 | AC20: 5654
A21: order backlog service
A22: order backlog offshore
A23: order backlog onshore
A24: average selling price onshore | C24: 0.83 | D24: 0.89 | E24: 0.82 | F24: 0.76 | G24: 0.63 | H24: 0.63 | I24: 0.63 | J24: 0.69 | K24: 0.63 | L24: 0.73 | M24: 0.78 | N24: 0.63 | O24: 0.71 | P24: 0.8 | Q24: 0.67 | R24: 0.75 | S24: 0.7 | T24: 0.74 | U24: 0.72 | V24: 0.87 | W24: 0.92 | X24: 0.86 | Y24: 0.98 | Z24: 0.95 | AA24: 0.91 | AB24: 0.91 | AC24: 0.96
A27: market share onshore
A28: EMEA [%][M€] | C28: 73 | F28: 78
A29: Americas [%][M€] | C29: 3 | F29: 7
A30: APAC [%][M€] | C30: 25 | F30: 15
B42: FY26 | C42: FY25 | D42: FY24 | E42: FY23 | F42: FY22 | G42: FY21 | H42: FY20 | I42: FY19 | J42: FY18 | K42: FY17 | L42: FY16
A43: Average selling price (onshore) | F43: 0.82 | G43: 0.65 | H43: 0.67 | I43: 0.73 | J43: 0.73
A44: Total revenue (€m) | C44: 10375 | D44: 10008 | E44: 9092 | F44: 9814 | G44: 10198 | H44: 9483 | I44: 10227 | J44: 9122 | K44: 10964 | L44: 10441
A45: Revenue - Turbines / New Units (€m) | C45: 7996 | D45: 7564 | E45: 7032 | F45: 7618 | G45: 8272 | H45: 7715 | I45: =3508+5225 -> 8733 | J45: 7847 | K45: 9766 | L45: 9372
A46: Revenue - Service (€m) | C46: 2379 | D46: 2442 | E46: 2059 | F46: 2196 | G46: 1926 | H46: 1768 | I46: 1493 | J46: 1275 | K46: 1198 | L46: 1069
A47: net profit | C47: -1711 | D47: -1721 | E47: -4439 | F47: -940 | G47: -627 | H47: -918 | I47: 140 | J47: 70
A48: WTG volume [MW] | C48: =C49+C50 -> 0 | D48: =D49+D50 -> 0 | E48: =E49+E50 -> 0 | F48: =F49+F50 -> 7652 | G48: =G49+G50 -> 10995 | H48: =H49+H50 -> 9968 | I48: =I49+I50 -> 9492 | J48: =J49+J50 -> 11234 | ... L48: =L49+L50 -> 0
A49: WTG volume [MW] onshore | F49: 4610 | G49: 8298 | H49: 7704 | I49: 6936 | J49: 8962 | K49: 6321
A50: WTG volume [MW] offshore | F50: 3042 | G50: 2697 | H50: 2264 | I50: 2556 | J50: 2272 | K50: 1732
A51: Total order intake (€m) | C51: 9324 | D51: 7255 | E51: 16836 | F51: 11598 | G51: 12185 | H51: 14736 | I51: 12749 | J51: 11872 | K51: 10917
A52: Total order onshore(€m) | F52: 2822 | G52: 4708 | I52: 6934 | J52: 6682 | K52: 5129
A53: Total order offshore(€m) | F53: 4380 | G53: 4068 | I53: 3100 | J53: 2795 | K53: 3336
A54: Order intake - Service (€m) | F54: 4396 | G54: 3409 | I54: 2715 | J54: 2395 | K54: 2451
A57: Employees | G57: 26000 | H57: 26000 | I57: 24500
A59: order backlog onshore | F59: 5.939 | G59: 6.212 | I59: 7.07 | J59: 5.1 | K59: 3.6 | L59: 4.8
...

Sheet 2026
B1: date | C1: country | D1: size [MW] | E1: Service time [years] | F1: customer | G1: # | H1: platform | I1: Rotor | J1: MW | K1: #.1 | L1: platform.1 | M1: Rotor.1 | N1: MW.1 | O1: Tower height | P1: wind farm | Q1: installation q | R1: Installation y | S1: note | T1: owner | U1: link
B2: 46059 | C2: New Zealand | D2: 94.6 | F2: Yinson Renewables | G2: 22 | H2: SG 4.3-130 | S2: Wind farm expected to generate over 300 GWh annually once operational
B3: 46059 | C3: Germany | D3: 21 | F3: GETEC green energy | G3: 3 | H3: SG 7.0-170 | S3: First SG 7.0-170 orders in Germany; article notes combined installation and maintenance
B4: 46062 | C4: Germany | D4: 42 | F4: Stadtwerke Münster | G4: 6 | H4: SG 7.0-170 | S4: Expected annual production of 130 GWh; 6 turbines 250 m tall; will power ~42,000 households
A24: =SUM(D2:D22) -> 157.6

Sheet 2025
B1: date | C1: country | D1: size [MW] | E1: Service time [years] | F1: customer | G1: # | H1: platform | I1: Rotor | J1: MW | K1: #.1 | L1: platform.1 | M1: Rotor.1 | N1: MW.1 | O1: Tower height | P1: wind farm | Q1: installation q | R1: Installation y | S1: note | T1: owner | U1: link
B2: 45838 | C2: Spain | D2: 40 | F2: Iberdrola-related (reported by industry press) | G2: 8 | H2: SG 5.0-145 | P2: Labraza wind farm (Basque Country) | S2: First reported order after the onshore restart; industry press reports the deal and turbine model/capacity.
B3: 45856 | C3: Germany | D3: 976.5 | F3: Skyborn Renewables | G3: 63 | H3: SG 14-236 | P3: Gennaker offshore wind farm | S3: Skyborn press release confirms turbine supply + long-term service agreement and gives the 63 turbines / 976.5 MW figure.
B4: 45867 | C4: Poland | D4: 390 | F4: Ocean Winds | G4: 26 | H4: SG 14-236 | P4: BC-Wind offshore wind farm | S4: Ocean Winds announcement confirms agreement with Siemens Gamesa; industry press repeats 26 turbines / 390 MW.
B5: 45916 | C5: Taiwan | D5: 495 | F5: Synera Renewable Energy (SRE) | G5: 35 | H5: SG 14-236 | P5: Formosa 4 offshore wind farm | S5: Article states 35 × 14 MW turbines selected for Formosa 4 and references the 495 MW project size
A24: =SUM(D2:D22) -> 1901.5

Sheet 2024
B1: date | C1: country | D1: size [MW] | E1: Service time [years] | F1: customer | G1: # | H1: platform | I1: Rotor | J1: MW | K1: #.1 | L1: platform.1 | M1: Rotor.1 | N1: MW.1 | O1: Tower height | P1: wind farm | Q1: installation q | R1: Installation y | S1: note | T1: owner | U1: link
B2: 45338 | C2: Poland | D2: 1440 | F2: Equinor + Polenergia JV | G2: 100 | H2: SG 14-236 DD | I2: 236 | J2: 14.4 | P2: Bałtyk II & Bałtyk III offshore wind farms (combined) | S2: Final contracts signed (manufacture/supply/service) | U2: OffshoreWind.biz :contentReference[oaicite:8]{index=8}; Polenergia announcement :contentReference[oaicite:9]{index=9}
B3: 45433 | C3: Germany | D3: 315 | F3: Iberdrola | G3: 21 | H3: SG 14-236 DD | I3: 236 | J3: 15 | P3: Windanker offshore wind farm (Baltic Sea) | S3: Turbines stated for project; order wording varies by source (selection/contract context) | U3: OffshoreWind.biz :contentReference[oaicite:10]{index=10}; Iberdrola project page (model) :contentReference[oaicite:11]{index=11}
B4: 45462 | C4: Germany | D4: 945 | F4: Skyborn Renewables | G4: 63 | H4: SG 14-236 DD | I4: 236 | J4: 15 | P4: Gennaker offshore wind farm (updated Master Supply Agreement) | S4: Updated Master Supply Agreement (precedes 2025 TSA; reported as turbine supply agreement/update) | U4: BalticWind.eu :contentReference[oaicite:12]{index=12}; Windpower Monthly roundup :contentReference[oaicite:13]{index=13}
B5: 45607 | C5: United Kingdom (England) | D5: 960 | F5: ScottishPower (Iberdrola) | G5: 64 | H5: SG 14-236 DD | I5: 236 | J5: 14 | P5: East Anglia TWO offshore wind farm | S5: Turbine Supply Agreement / contract (~£1bn+ reported) | U5: Siemens Gamesa press release :contentReference[oaicite:14]{index=14}; Reuters :contentReference[oaicite:15]{index=15}; OffshoreWind.biz :contentReference[oaicite:16]{index=16}
A24: =SUM(D2:D22) -> 3660

Sheet 2023
B1: date | C1: country | D1: size [MW] | E1: Service time [years] | F1: customer | G1: # | H1: platform | I1: Rotor | J1: MW | K1: # | L1: platform | M1: Rotor | N1: MW | O1: Tower height | P1: wind farm | Q1: installation q | R1: Installation y | T1: note | V1: owner | X1: link
B2: 44938 | C2: Denmark | D2: 1000 | F2: RWE | G2: 72 | H2: SG 14-236 DD | I2: 236 | J2: 14 | P2: Thor | Q2: 1 | R2: 2026 | X2: https://www.siemensgamesa.com/en-int/-/media/siemensgamesa/downloads/en/newsroom/2023/01/siemens-gamesa-press-release-offshore-wind-plant-thor-denmark.pdf
B3: 45014 | C3: UK | D3: 1400 | E3: 8 | F3: ScottishPower Renewables | G3: 95 | H3: SG 14-236 DD | I3: 236 | J3: 14 | P3: East Anglia 3 | R3: 2026 | T3: 69 km offshore
B4: 45028 | C4: India | D4: 166 | F4: ArcelorMittal | G4: 46 | H4: SG 3.6-145 | I4: 145 | J4: 3.6 | T4: Andhra Pradesh
B5: 45036 | C5: Poland | D5: 1500 | E5: 5 | F5: PGE and Ørsted | G5: 107 | H5: SG 14-236 DD | I5: 236 | J5: 14 | R5: 2027 | T5: 40 km offshore
B6: 45054 | C6: Spain | D6: 324 | E6: 5 | F6: Repsol | G6: 40 | H6: SG 5.0-145 | I6: 145 | J6: 5
A24: =SUM(D2:D22) -> 4390

Sheet 2022
B1: date | C1: country | D1: size [MW] | E1: Service time [years] | F1: customer | G1: # | H1: platform | I1: Rotor | J1: MW | K1: # | L1: platform | M1: Rotor | N1: MW | O1: Tower height | P1: wind farm | Q1: installation q | R1: Installation y | T1: note | V1: owner | X1: link
B2: 44910 | C2: Finland | D2: 145 | E2: 35 | F2: OX2 | G2: 22 | H2: SG 6.6-170 | I2: 170 | J2: 6.6 | O2: 165 | P2: Niinimäki | Q2: 4 | R2: 2024 | X2: https://www.siemensgamesa.com/-/media/siemensgamesa/downloads/en/newsroom/2022/12/siemens-gamesa-press-release-onshore-ox2-niinimaki-finland.pdf
B3: 44909 | C3: Spain | D3: 52 | E3: 20 | F3: Capital Energy | G3: 10 | H3: SG 5.0-145 | I3: 145 | J3: 5 | P3: Albactet | Q3: 2 | R3: 2024 | X3: https://www.siemensgamesa.com/-/media/siemensgamesa/downloads/en/newsroom/2022/12/siemens-gamesa-press-release-capital-energy-contract-la-herrada-spain.pdf
B4: 44879 | C4: Sweden | D4: 70 | E4: 35 | F4: OX2 | G4: 11 | H4: SG 6.6-170 | I4: 170 | J4: 6.6 | O4: 115 | P4: Riberget | R4: 2024 | X4: https://www.siemensgamesa.com/-/media/siemensgamesa/downloads/en/newsroom/2022/11/siemens-gamesa-press-release-onshore-riberget-sweden-5x.pdf
B5: 44854 | C5: Finland | D5: 105 | E5: 35 | F5: Energiequelle | G5: 16 | H5: SG 6.6-170 | I5: 170 | J5: 6.6 | O5: 145 | Q5: 2 | R5: 2024 | X5: https://www.siemensgamesa.com/newsroom/2022/10/102022-siemens-gamesa-press-release-onshore-finland-mikonkeidas-energiequelle
B6: 44853 | C6: Taiwan | D6: 1044 | E6: 15 | F6: Hai long | G6: 73 | H6: SG 14-222 DD | I6: 222 | J6: 14 | T6: FID 2023 | X6: https://www.siemensgamesa.com/newsroom/2022/10/101922-siemens-gamesa-press-release-offshore-hai-long--taiwan
B7: 44795 | C7: Romania | D7: 48 | E7: 20 | F7: Eurowind energy | G7: 8 | H7: SG 6.6-170 | I7: 170 | J7: 6.6 | O7: 135 | P7: Pecineaga | Q7: 3 | R7: 2024 | X7: https://www.siemensgamesa.com/newsroom/2022/08/082222-siemens-gamesa-press-release-romania-onshore-eurowind-pecineaga
B8: 44785 | C8: India | D8: =G8*J8 -> 345.6 | F8: Azure Power india | G8: 96 | H8: SG 3.6-145 | I8: 145 | J8: 3.6 | Q8: 2 | R8: 2023 | X8: https://www.siemensgamesa.com/newsroom/2022/08/081122-siemens-gamesa-press-release-azure-india-onshore-project
B9: 44784 | C9: Philippines | D9: 70 | F9: ACEN | G9: 14 | H9: SG 5.0-145 | I9: 145 | J9: 5 | P9: capa | X9: https://www.siemensgamesa.com/newsroom/2022/08/081122-siemens-gamesa-press-release-acen-philippines-pagudpud-caparispisa-onshore
B10: 44771 | C10: Japan | D10: 113 | E10: 15 | G10: 14 | H10: SG 8.0-167 | I10: 167 | J10: 8 | P10: Ishikari | Q10: 3 | R10: 2023 | X10: https://www.siemensgamesa.com/newsroom/2022/07/072922-siemens-gamesa-press-release-first-offshore-project-ishikari-japan
B11: 44761 | C11: Sweden | D11: 277 | E11: 35 | F11: Arise and Foresight | G11: 42 | H11: SG 6.6-170 | I11: 170 | J11: 6.6 | K11: 1 | L11: SG 6.6-155 | M11: 155 | N11: 6.6 | P11: Kölvallen | Q11: 1 | R11: 2025 | X11: https://www.siemensgamesa.com/newsroom/2022/07/071822-siemens-gamesa-press-release-kolvallen-sweden-project-onshore
B12: 44748 | C12: Spain | D12: 60 | E12: 25 | F12: Kineses Enerji | G12: 10 | H12: SG 5.0-145 | I12: 145 | J12: 5 | Q12: 2 | R12: 2024 | X12: https://www.siemensgamesa.com/newsroom/2022/07/070622-siemens-gamesa-press-release-kinesis-enerji-spain-onshore
B13: 44747 | C13: South Korea | D13: 75 | E13: 20 | F13: SK D&D | G13: 15 | H13: SG 5.0-145 | I13: 145 | J13: 5 | R13: 2024 | X13: https://www.siemensgamesa.com/newsroom/2022/07/070522-siemens-gamesa-press-release-sk-gunwi-korea-onshore
B14: 44746 | C14: Germany | D14: 927 | E14: 20 | F14: wpd | G14: 103 | H14: SG 8.6-167 DD | I14: 167 | J14: 8.6 | P14: Gennaker | R14: 2026 | X14: https://www.siemensgamesa.com/newsroom/2022/07/070422-siemens-gamesa-press-release-offshore-gennaker-germany
B15: 44739 | C15: Germany | D15: 913 | F15: Ørsted | G15: 83 | H15: SG 11.0-200 DD | I15: 200 | J15: 11 | P15: Borkum Riffgrund 3 | R15: 2024 | X15: https://www.siemensgamesa.com/newsroom/2022/06/062422-siemens-gamesa-press-release-borkum-offshore-order
B16: 44739 | C16: Poland | D16: 350 | F16: RWE | G16: 25 | H16: SG 14-236 DD | I16: 236 | J16: 14 | P16: Baltic II | R16: 2024 | X16: https://www.siemensgamesa.com/newsroom/2022/06/062722-siemens-gamesa-press-relelase-rwe-accelerate-offshore-market-poland
B17: 44734 | C17: UK | D17: 882 | F17: Moray West | G17: 60 | H17: SG 14-222 DD | I17: 222 | J17: 14 | R17: 2024 | T17: Scotland | X17: https://www.siemensgamesa.com/newsroom/2022/06/062122-siemens-gamesa-press-release-west-moray-offshore
B18: 44722 | C18: India | D18: 133 | G18: 37 | H18: SG 3.6-145 | I18: 145 | J18: 3.6 | R18: 2023 | X18: https://www.siemensgamesa.com/newsroom/2022/06/061022-siemens-gamesa-press-release-vena-energy-india-133mw
B19: 44711 | C19: Spain | D19: 110 | E19: 25 | F19: Greenalia | G19: 22 | H19: SG 5.0-145 | I19: 145 | J19: 5 | Q19: 4 | R19: 2023 | X19: https://www.siemensgamesa.com/newsroom/2022/05/053022-siemens-gamesa-press-release-greenalia-campelos-spain-110mw
B20: 44701 | C20: Serbia | D20: 66 | F20: EPS | G20: 20 | H20: SG 3.3-132 | I20: 132 | J20: 3.3 | R20: 2024 | X20: https://www.siemensgamesa.com/newsroom/2022/05/051822-siemens-gamesa-press-release-serbia-eps-project
B21: 44614 | C21: Poland | D21: 1440 | G21: 103 | H21: SG 14-236 DD | I21: 236 | J21: 14 | P21: Baltyk II & III | R21: 2025 | T21: preferred supplier, FID 2024 | X21: https://www.siemensgamesa.com/newsroom/2022/02/220222-siemens-gamesa-press-release-baltyk-ii-iii-poland
B22: 44579 | C22: Spain | D22: 64 | E22: 5 | F22: Iberdrola | G22: 14 | H22: SG 6.6-170 | I22: 170 | J22: 6.6 | K22: 2 | L22: SG 5.0-145 | R22: 2023 | X22: https://www.siemensgamesa.com/newsroom/2022/01/220118-siemens-gamesa-press-release-siemens-gamesa-press-release-iberdrola-spain-5x-onshore
A24: =SUM(D2:D22) -> 7289.6

Sheet 2021
B1: date | C1: country | D1: size [MW] | E1: Service time [years] | F1: customer | G1: # | H1: platform | I1: Rotor | J1: MW | K1: # | L1: platform | M1: Rotor | N1: MW | O1: Tower height | P1: wind farm | Q1: installation q | R1: Installation y | T1: note | V1: owner | X1: link
B3: 44560 | C3: Sweden | D3: 260 | E3: 25 | F3: Eolus | G3: 42 | H3: SG 6.6-170 | I3: 170 | J3: 6.6 | O3: 115-123 | P3: Stor-Skälsjön | R3: 2023 | X3: https://www.siemensgamesa.com/newsroom/2021/12/211230-siemens-gamesa-press-release-deal-eolus-hydro-rein-sweden-5x
B4: 44557 | C4: India | D4: 302 | F4: NIIF | G4: 84 | H4: SG 3.6-145 | I4: 145 | J4: 3.6 | R4: 2023 | X4: https://www.siemensgamesa.com/newsroom/2021/12/211227-siemens-gamesa-press-release-3-x-platfomr-ayana-renewable-power-india
B5: 44550 | C5: United states | D5: 2600 | E5: 10 | G5: 176 | H5: SG 14-222 | I5: 222 | J5: 14 | P5: Virginia offshore | R5: 2026 | T5: FID q1 2023 | X5: https://www.siemensgamesa.com/newsroom/2021/12/211220-siemens-gamesa-press-release-offshore-dominion-energy-usa
B6: 44550 | C6: Germany | D6: 242 | E6: 5 | F6: Ørsted | G6: 23 | H6: SG 11.0-200 DD | I6: 200 | J6: 11 | P6: Gode Wind 3 | R6: 2024 | X6: https://www.siemensgamesa.com/newsroom/2021/12/siemens-gamesa-press-release-offshore-gode-wind-3-firm-order
B7: 44545 | C7: Denmark | D7: 344 | E7: 3 | F7: Vattenfall | G7: 41 | H7: SG 8.0-167 DD | I7: 167 | J7: 8 | P7: Vestashav Nord + Syd | R7: 2023 | X7: https://www.siemensgamesa.com/newsroom/2021/12/211215-siemens-gamesa-press-release-vesterhav-projects-firm-order
B8: 44524 | C8: Finland | D8: 455 | E8: 35 | F8: OX2 | G8: 69 | H8: SG 6.6-170 | I8: 170 | J8: 6.6 | P8: Lestijärvi | R8: 2024 | X8: https://www.siemensgamesa.com/newsroom/2021/11/211124-siemens-gamesa-press-release-finland-lestijarvvi-455mw
B9: 44518 | C9: Canada | D9: 100 | F9: RES | G9: 20 | H9: SG 5.0-145 | I9: 145 | J9: 5.2 | P9: Hilda | X9: https://www.siemensgamesa.com/newsroom/2021/11/211118-siemens-gamesa-press-release-canada-order-hilda
B10: 44412 | C10: Sweden | D10: 242 | E10: 30 | F10: Arise | G10: 39 | H10: SG 5.8-170 | P10: Ranasjö + Salsjö | Q10: 1 | R10: 2024 | X10: https://www.siemensgamesa.com/newsroom/2021/08/210804-siemens-gamesa-press-release-sweden-twin-peaks
B11: 44397 | C11: India | D11: 322 | F11: ReNew | G11: 93 | H11: SG 3.4-145 | P11: Tondehal | X11: https://www.siemensgamesa.com/newsroom/2021/07/210720-siemens-gamesa-press-release-renew-india
B12: 44371 | C12: Spain | D12: 85 | E12: 15 | G12: 17 | H12: SG 5.0-145 | Q12: 3 | R12: 2022 | X12: https://www.siemensgamesa.com/newsroom/2021/06/210624-siemens-gamesa-press-release-spain-85mw
B13: 44352 | C13: Philippines | D13: 160 | E13: 5 | F13: UPC | G13: 18 | H13: SG 5.0-145 | K13: 14 | L13: SG 5.0-132 | R13: 2022 | X13: https://www.siemensgamesa.com/newsroom/2021/05/212605-siemens-gamesa-press-release-largest-wind-farm-philipines
B14: 44299 | C14: Peru | D14: 260 | G14: 50 | H14: SG 5.0-145 | J14: 5-5.2 | Q14: 1 | R14: 2023 | X14: https://www.siemensgamesa.com/newsroom/2021/04/210413-siemens-gamesa-press-release-peru-punta-lomitas
B15: 44286 | C15: UK | D15: 1400 | F15: RWE | G15: 100 | H15: SG 14-222 DD | I15: 222 | J15: 14 | P15: Sofia | R15: 2023 | T15: 195 km offshore, 35 m water depth, later announced that 40 turbines will be with recyclaBlade | X15: https://www.siemensgamesa.com/newsroom/2021/03/210330-siemens-gamesa-press-release-sofia-uk
B16: 44285 | C16: Spain | D16: 120 | F16: Repsol | G16: 24 | H16: SG 5.0-145 | Q16: 1 | R16: 2022 | X16: https://www.siemensgamesa.com/newsroom/2021/03/210330-siemens-gamesa-press-release-spain-repsol
B17: 44281 | C17: Sweden | D17: 86 | E17: 20 | F17: European Energy | G17: 6 | H17: SG 5.8-170 | P17: Grevekulla | R17: 2022 | X17: https://www.siemensgamesa.com/newsroom/2021/03/210326-siemens-gamesa-press-release-sweden-5x-european-energy
B18: 44280 | C18: Italy | D18: 97 | G18: 28 | H18: SG 3.4-132 | Q18: 2 | R18: 2022 | X18: https://www.siemensgamesa.com/newsroom/2021/03/210325-siemens-gamesa-press-release-italy-contracts
B19: 44265 | C19: New Zealand | D19: 176 | E19: 30 | F19: Meridian | G19: 41 | H19: SG 4.3 | X19: https://www.siemensgamesa.com/newsroom/2021/03/210310-siemens-gamesa-press-release-new-zeland
B20: 44264 | C20: Spain | D20: 150 | E20: 20 | G20: 30 | H20: SG 5.0-145 | X20: https://www.siemensgamesa.com/newsroom/2021/03/210309-siemens-gamesa-press-release-spain-elawan
B21: 44259 | C21: UK | D21: 50 | E21: 25 | G21: 8 | H21: SG 5.8-155 | P21: Longhill Burn | X21: https://www.siemensgamesa.com/newsroom/2021/03/210304-siemens-gamesa-press-release-pr-uk-5x-longhill
B22: 44249 | C22: France | D22: =G22*J22 -> 448 | E22: 15 | F22: EDF | G22: 64 | H22: SWT-7.0-154 | I22: 154 | J22: 7 | P22: Courseulles-sur-Mer | T22: 10 km offshore | X22: https://www.siemensgamesa.com/newsroom/2021/02/210222-siemens-gamesa-press-release-courseulles-firm-order
B23: 44238 | C23: The Netherlands | D23: =G23*J23 -> 759 | E23: 15 | F23: CrossWind | G23: 69 | H23: SG 11-200 DD | I23: 200 | J23: 11 | P23: Hollandse Kust Noord | X23: https://www.siemensgamesa.com/newsroom/2021/02/210211-siemens-gamesa-press-release-759-mw-offshore
B24: 44236 | C24: Sweden | D24: 62 | E24: 30 | F24: Tekniska verken | G24: 7 | H24: SG 5.8-170 | O24: 115 | P24: Fryksdalshöjden | Q24: 4 | R24: 2022 | X24: https://www.siemensgamesa.com/newsroom/2021/02/210209-siemens-gamesa-press-release-sweden-5x-deal-tekniska-verken
B25: 44218 | C25: Brazil | D25: 434 | G25: 70 | H25: SG 5.8-170 | P25: Santo Agostinho | X25: https://www.siemensgamesa.com/newsroom/2021/01/210122-siemens-gamesa-press-release-brasil-engie
B26: 44214 | C26: Finland | D26: 81 | F26: Suomen Hyötytuuli Oy | G26: 14 | H26: SG 5.8-155 | R26: 2022 | X26: https://www.siemensgamesa.com/newsroom/2021/01/210118-siemens-gamesa-press-release-81mw-finland
B27: 44211 | C27: Vietnam | D27: 100 | F27: Gia Lai Investment and Development Wind Power JSC | G27: 25 | H27: SG 4.X-145 | J27: =D27/G27 -> 4 | Q27: 3 | R27: 2021 | X27: https://www.siemensgamesa.com/newsroom/2021/01/210115-siemens-gamesa-press-release-hunghai-vietnam
B28: 44211 | C28: Vietnam | D28: 117 | G28: 29 | H28: SG 4.X-145 | X28: https://www.siemensgamesa.com/newsroom/2021/01/210115-siemens-gamesa-press-release-hanbaram-vietnam
B29: 44200 | C29: Ethiopia | D29: 100 | F29: EEP | G29: 29 | H29: SG 3.4-132 | Q29: 2 | R29: 2023 | X29: https://www.siemensgamesa.com/newsroom/2021/01/210104-siemens-gamesa-press-release-first-wind-farm-ethiopia-en
A31: =SUM(D2:D29) -> 9552

Sheet 2020
B1: date | C1: country | D1: size [MW] | E1: Service time [years] | F1: customer | G1: # | H1: platform | I1: Rotor | J1: MW | K1: # | L1: platform | M1: Rotor | N1: MW | O1: Tower height | P1: wind farm | Q1: installation q | R1: Installation y | T1: note | V1: owner | X1: link
B3: 44188 | C3: Sweden | D3: 66 | E3: 25 | F3: Rabbalshede kraft | G3: 10 | H3: SG 5.8-155 | I3: 155 | Q3: 3 | R3: 2022 | X3: https://www.siemensgamesa.com/newsroom/2020/12/201223-siemens-gamesa-press-release-pr-5x-femstenaberg
B4: 44187 | C4: Brazil | D4: 465 | G4: 75 | H4: SG 5.8-170 | I4: 170 | Q4: 4 | R4: 2022 | X4: https://www.siemensgamesa.com/newsroom/2020/12/201222-siemens-gamesa-press-release-brazil-america-patria-onshore
B5: 44181 | C5: United states | D5: 298 | E5: 30 | F5: Ørsted | G5: 51 | H5: SG 5.0-145 | I5: 145 | Q5: 4 | R5: 2021 | T5: Nebraska | X5: https://www.siemensgamesa.com/newsroom/2020/12/201216-siemens-gamesa-press-release-haystack-orsted-usa
B6: 44167 | C6: Sweden | D6: 37 | E6: 20 | F6: European energy | G6: 6 | H6: SG 5.8-170 | I6: 170 | J6: 6.2 | P6: Kingebol | Q6: 3 | R6: 2022 | X6: https://www.siemensgamesa.com/newsroom/2020/12/201202-siemens-gamesa-press-release-european-energy-sweden-poland
B7: 44167 | C7: Poland | D7: 19.4 | E7: 20 | F7: European energy | G7: 9 | H7: SG 2.X | J7: 2 | Q7: 1 | R7: 2022 | X7: https://www.siemensgamesa.com/newsroom/2020/12/201202-siemens-gamesa-press-release-european-energy-sweden-poland
B8: 44159 | C8: Canada | D8: 130 | F8: Berkshire Hathaway Energy | G8: 26 | H8: SG 5.0-145 | I8: 145 | P8: Rattlesnake | Q8: 1 | R8: 2022 | X8: https://www.siemensgamesa.com/newsroom/2020/11/201124-siemens-gamesa-press-release-canada-130-mw-order-sg-5-0-145
B9: 44110 | C9: Sweden | D9: 372 | E9: 15 | G9: 60 | H9: SG 5.8-170 | I9: 170 | J9: 6.2 | P9: Björnberget | R9: 2022 | X9: https://www.siemensgamesa.com/newsroom/2020/10/201006-siemens-gamesa-press-release-largest-5x-deal-bjornberget
B10: 44105 | C10: Pakistan | D10: 260 | G10: 130 | H10: SG 2.X | J10: 2 | Q10: 1 | R10: 2021 | X10: https://www.siemensgamesa.com/newsroom/2020/09/201001-siemens-gamesa-press-release-pakistan-storage
B11: 44104 | C11: Sweden | D11: 68.4 | E11: 15 | F11: Eolus Vind | G11: 7 | H11: SG 5.8-170 | I11: 170 | K11: 4 | L11: SG 5.8-155 | M11: 155 | N11: 5.8 | R11: 2023 | X11: https://www.siemensgamesa.com/newsroom/2020/09/200930-siemens-gamesa-press-release-sweden-5x-eolus-vind
B12: 44074 | C12: United states | D12: 325 | G12: 65 | H12: SG 5.0-145 | I12: 145 | Q12: 3 | R12: 2021 | T12: Texas | X12: https://www.siemensgamesa.com/newsroom/2020/08/200831-siemens-gamesa-press-release-texas-325mw-project
B13: 44060 | C13: India | D13: 473 | G13: 215 | H13: SG 2.2-122 | I13: 122 | Q13: 3 | R13: 2021 | X13: https://www.siemensgamesa.com/newsroom/2020/08/200817-siemens-gamesa-press-release-india-adani-green-energy
B14: 44036 | C14: Chile | D14: 110 | E14: 10 | G14: 22 | H14: SG 5.0-145 | I14: 145 | P14: Cabo Leones III | Q14: 3 | R14: 2021 | X14: https://www.siemensgamesa.com/newsroom/2020/07/200724-siemens-gamesa-press-release-cabo-leones-3-chile
B15: 44036 | C15: Chile | D15: 60 | E15: 12 | F15: EDF | G15: 12 | H15: SG 5.0-145 | I15: 145 | Q15: 1 | R15: 2021 | X15: https://www.siemensgamesa.com/newsroom/2020/07/200724-siemens-gamesa-press-release-cabo-leones-1-chile
B16: 44035 | C16: Vietnam | D16: 78 | E16: 10 | G16: 18 | H16: SG 5.0-145 | I16: 145 | P16: Hiep Thanh | Q16: 3 | R16: 2021 | X16: https://www.siemensgamesa.com/newsroom/2020/07/200723-siemens-gamesa-press-release-vietnam-78-mw
B17: 44013 | C17: Pakistan | D17: 50 | G17: 25 | H17: SG 2.X | J17: 2 | Q17: 1 | R17: 2021 | X17: https://www.siemensgamesa.com/newsroom/2020/09/201001-siemens-gamesa-press-release-pakistan-storage
B18: 44004 | C18: Germany | D18: 52.8 | E18: 20 | G18: 12 | H18: SWT-DD-142 | I18: 142 | J18: 4.1 | K18: 1 | L18: SWT-3.6-130 | M18: 130 | N18: 3.6 | O18: 165 | P18: coesfeld | Q18: 4 | R18: 2020 | T18: Hybrid towers (concrete and steel) | X18: https://www.siemensgamesa.com/newsroom/2020/06/200622-siemens-gamesa-press-release-wind-farm-coesfeld
B19: 43984 | C19: France | D19: 497 | E19: 15 | F19: EDF | G19: 71 | H19: SWT-7.0-154 | I19: 154 | J19: 7 | P19: Fecamp | Q19: 4 | R19: 2021 | X19: https://www.siemensgamesa.com/newsroom/2020/06/200602-siemens-gamesa-press-release-fecamp-vinci
B20: 43980 | C20: France | D20: 496 | E20: 10 | F20: Iberdrola | G20: 62 | H20: SG 8.0-167 DD | I20: 167 | J20: 8 | P20: Bay of Saint Brieuc | R20: 2023 | X20: https://www.siemensgamesa.com/newsroom/2020/05/200529-siemens-gamesa-bay-of-saint-brieuc-offshore
B21: 43941 | C21: Poland | D21: 184 | G21: 63 | J21: =D21/G21 -> 2.9206349 | T21: from auction in 2019 | X21: https://www.siemensgamesa.com/newsroom/2020/04/200420-siemens-gamesa-poland-auctions
B22: 43936 | C22: Sweden | D22: 85.8 | E22: 15 | F22: RES | G22: 13 | H22: SG 5.8-155 | I22: 155 | J22: =D22/G22 -> 6.6 | P22: Rödene | R22: 2021 | X22: https://www.siemensgamesa.com/newsroom/2020/04/200415-siemens-gamesa-rodene-sweden-5x
B23: 43924 | C23: Germany | D23: 342 | E23: 2 | G23: 38 | H23: SG 8.0-167 DD | I23: 167 | J23: 8 | P23: Kaskasi | Q23: 3 | R23: 2022 | T23: Later announced that some blade will be recyclaBlade | X23: https://www.siemensgamesa.com/newsroom/2020/04/200403-siemens-gamesa-kaskasi
B24: 43922 | C24: Pakistan | D24: 50 | G24: 25 | H24: SG 2.X | J24: 2 | Q24: 4 | R24: 2020 | X24: https://www.siemensgamesa.com/newsroom/2020/09/201001-siemens-gamesa-press-release-pakistan-storage
B25: 43922 | C25: Brazil | D25: 312 | F25: AES | G25: 52 | H25: SG 5.8-170 | I25: 170 | J25: =D25/G25 -> 6 | R25: 2021 | X25: https://www.siemensgamesa.com/newsroom/2020/03/010420-siemens-gamesa-tucano-brazil
B26: 43916 | C26: Sweden | D26: 46 | E26: 25 | F26: Eurowind Energy A/S | G26: 8 | H26: SG 5.8-170 | I26: 170 | J26: =D26/G26 -> 5.75 | O26: 115 | P26: Knöstad | Q26: 3 | R26: 2021 | X26: https://www.siemensgamesa.com/newsroom/2020/03/200326-siemens-gamesa-order-knostad-sweden
B27: 43885 | C27: Djibouti | D27: 59 | F27: Electricité de Djibouti | G27: 17 | H27: SG 3.4-132 | J27: =D27/G27 -> 3.4705882 | Q27: 3 | R27: 2021 | X27: https://www.siemensgamesa.com/newsroom/2020/02/200225-siemens-gamesa-djibouti-en
A28: prev. Year? | B28: 43831 | C28: Pakistan | D28: 50 | G28: 25 | H28: SG 2.X | J28: 2 | Q28: 4 | R28: 2020 | X28: https://www.siemensgamesa.com/newsroom/2020/09/201001-siemens-gamesa-press-release-pakistan-storage
A30: =SUM(D2:D29) -> 4986.4

Sheet 2019
B1: date | C1: country | D1: size [MW] | E1: Service time [years] | F1: customer | G1: # | H1: platform | I1: Rotor | J1: MW | K1: #.1 | L1: platform.1 | M1: Rotor.1 | N1: MW.1 | O1: Tower height | P1: wind farm | Q1: installation q | R1: Installation y | S1: note | T1: owner | U1: link
B2: 28-11-2019 | C2: UK | D2: 448 | H2: SG 8.0-167 DD | I2: 167 | J2: 8 | P2: Gaoithe | R2: 2023 | S2: Siemens Gamesa celebrates ‘the Strength of the Wind’ with firm 448 MW Scottish offshore order | U2: https://p3.aprimocdn.net/siemensenergy/3cc82e9f-e547-43c7-9591-b15400f3c848/press-release-siemens-gamesa-scottish-offhore-order-en-pdf_Original%20file.pdf
B3: 13-11-2019 | C3: Taiwan | D3: 300 | P3: Taiwan. The | S3: Siemens Gamesa named preferred supplier for 300 MW Hai Long 2 offshore wind project in Taiwan | U3: https://p3.aprimocdn.net/siemensenergy/076fbe81-1d0b-4e87-9a79-b15400f3bb8d/pressrelease-siemens-gamesa-Hai-Long-300MW-en-pdf_Original%20file.pdf
B4: 07-11-2019 | C4: Sweden | D4: 254 | E4: 30 | G4: 62 | P4: MW Stavro | R4: 2021 | S4: Clean, green search for Google´s users, as Siemens Gamesa’s wind turbines in Sweden will power its data center | U4: https://p3.aprimocdn.net/siemensenergy/05f873f9-92fa-4364-a4cd-b15400f3d0fe/pressrelease-siemens-gamesa-stavro-sweden-en-pdf_Original%20file.pdf
B5: 17-10-2019 | C5: Chile | D5: 359 | G5: 82 | H5: SG 4.5-145 | I5: 145 | J5: 4.5 | S5: Three new contracts for 359 MW in Chile help Siemens Gamesa surpass a company country record | U5: https://p3.aprimocdn.net/siemensenergy/866f51b3-02e4-4118-8fc4-b15400f37f9f/pressrelease-siemens-gamesa-chile-record-pdf_Original%20file.pdf
B6: 04-10-2019 | C6: China | D6: 200 | F6: First | R6: 2020 | S6: First order for 200 MW supply contract in China for the Siemens Gamesa 4.X platform | U6: https://p3.aprimocdn.net/siemensenergy/23a1ec43-06bc-4c18-9e1f-b15400f3849f/pressrelease-siemens-gamesa-china-200-MW-TBEA-ENG-pdf_Original%20file.pdf
B7: 28-08-2019 | C7: Canada | D7: 95 | F7: MidAmerican | H7: SG 4.5-145 | I7: 145 | J7: 4.5 | P7: MW Southern Hills Expansion | S7: Siemens Gamesa reinforces its partnership with MidAmerican with 95 MW Southern Hills Expansion project in the U.S. | U7: https://p3.aprimocdn.net/siemensenergy/cebaedb1-06b9-4854-ab40-b15400f35526/pressrelease-siemens-gamesa-southern-hill-100mw-usa-en-pdf_Original%20file.pdf
B8: 24-07-2019 | C8: Brazil | D8: 94 | F8: Brennand Investimentos | H8: SG 3.4-132 | I8: 132 | J8: 3.4 | R8: 2020 | S8: Siemens Gamesa signs first contract with Brennand Investimentos in Brazil for the supply of 94 MW | U8: https://www.siemensgamesa.com/global/en/home/press-releases/190724-siemens-gamesa-onshore-brennand-brazil.html
B9: 22-07-2019 | C9: Vietnam | D9: 32 | E9: 10 | H9: SG 4.5-145 | I9: 145 | J9: 4.5 | P9: Thanh Hai | R9: 2020 | S9: Siemens Gamesa will supply the SG 4.5-145 for its first nearshore project in Vietnam | U9: https://www.siemensgamesa.com/global/en/home/press-releases/190722-siemens-gamesa-nearshore-project-vietnam.html
B10: 17-06-2019 | C10: Taiwan | D10: 376 | E10: 20 | H10: SG8.0-167 DD | I10: 167 | J10: 8 | P10: Taiwan. 47 SG8.0-167 DD offshore wind turbines to be provided 20-year full Servic | S10: Siemens Gamesa conditionally awarded order for 376 MW Formosa 2 offshore wind project in Taiwan | U10: https://www.siemensgamesa.com/global/en/home/press-releases/190617-formosa2-project-offshore-wind-taiwan.html
B11: 31-05-2019 | C11: Taiwan | D11: 640 | E11: 15 | H11: SG 8.0-167 DD | I11: 167 | J11: 8 | P11: Taiwan. Contract includes delivery of 80 SG 8.0-167 DD offshore wind turbines and | R11: 2020 | S11: Siemens Gamesa receives firm order for wpd’s 640 MW Yunlin offshore wind power project in Taiwan | U11: https://www.siemensgamesa.com/global/en/home/press-releases/190531-siemens-gamesa-news-contract-taiwan-640mw.html
B12: 22-05-2019 | C12: United States | D12: 1000 | H12: SG 4.5-145 | I12: 145 | J12: 4.5 | L12: SG 2.7-129 | M12: 129 | N12: 2.7 | P12: MW Milligan | S12: Siemens Gamesa reaches 1 GW sold of the SG 4.5-145 with 232 MW Milligan project for EDF Renewables in the USA | U12: https://www.siemensgamesa.com/global/en/home/press-releases/190522-siemens-gamesa-news-sg-4-5-145-for-the-milligan-wind-farm-in-the-usa.html
B13: 26-04-2019 | C13: Canada | D13: 194 | H13: SG 4.5-145 | I13: 145 | J13: 4.5 | P13: Canada with an undisclosed customer. The order is for a nominal capacity of 194 M | S13: Siemens Gamesa receives a new order for 43 SG 4.5-145 turbines to be installed in Canada | U13: https://www.siemensgamesa.com/global/en/home/press-releases/190426-siemens-gamesa-news-onshore-turbines-sg-4-5-145-for-canada.html
B14: 25-04-2019 | C14: United States | D14: 487 | H14: SG 4.5-145 | I14: 145 | J14: 4.5 | L14: SWT-2.3-108 | M14: 108 | N14: 2.3 | P14: MW Coyote | R14: 2020 | S14: Siemens Gamesa secures two orders in the U.S. for its SG 4.5-145 wind turbine totaling 487 MW | U14: https://www.siemensgamesa.com/global/en/home/press-releases/190425-siemens-gamesa-news-onshore-order-usa-turbine-sg-4-5-145.html
B15: 16-04-2019 | C15: France | D15: 1000 | H15: SWT-7.0-154 DD | I15: 154 | J15: 7 | P15: Le Havre. Siemens Gamesa remains fully committed to meeting the needs of all its | S15: Siemens Gamesa selected by Eolien Maritime France as preferred supplier to supply and service nearly 1 GW of offshore wind projects in France | U15: https://www.siemensgamesa.com/global/en/home/press-releases/190416-siemens-gamesa-france-offshore-new-project.html
B16: 15-04-2019 | C16: United States | H16: SG 10.0-193 DD | I16: 193 | J16: 10 | L16: SG 8.0-167 DD | M16: 167 | N16: 8 | P16: MW Lillgrund | S16: Siemens Gamesa is on track with the new SG 10.0-193 DD wind turbine for the world’s first zero subsidy offshore wind farm | U16: https://www.siemensgamesa.com/global/en/home/press-releases/190415-siemens-gamesa-news-offshore-sg-10-0-193-dd-for-zero-subsidy-offshore-wind-farm.html
B17: 21-03-2019 | C17: Brazil | D17: 3100 | H17: SG 3.4-132 | I17: 132 | J17: 3.4 | L17: SG 2.1-114 | M17: 114 | N17: 2.1 | S17: Siemens Gamesa awarded financing certificate for its SG 3.4-132 onshore wind turbine in Brazil | U17: https://www.siemensgamesa.com/global/en/home/press-releases/21032019-siemens-gamesa-certificate-brazil.html
B18: 28-02-2019 | C18: China | D18: 21 | E18: 5 | F18: State Power Investment Corporation | H18: SG 3.4-132 | I18: 132 | J18: 3.4 | P18: China. The | R18: 2019 | S18: Siemens Gamesa to supply 21 MW in China, marking the first deal with State Power Investment Corporation | U18: https://www.siemensgamesa.com/global/en/home/press-releases/onshore-wind-power-plant-china-state-power-investment-corporation.html
B19: 05-02-2019 | C19: Spain | D19: 200 | E19: 10 | G19: 63 | H19: SG 3.4-132 | I19: 132 | J19: 3.4 | L19: SG 2.6-114 | M19: 114 | N19: 2.6 | P19: Navarra. This | S19: Siemens Gamesa reaffirms its leading position in Spain with new contracts to supply 200 MW | U19: https://www.siemensgamesa.com/global/en/home/press-releases/200-mw-in-spain-7-wind-farms.html
B20: 31-01-2019 | C20: India | D20: 567 | H20: SG 2.1-122 | I20: 122 | J20: 2.1 | P20: Bhuj | Q20: 1 | R20: 2020 | S20: Siemens Gamesa will supply 567 MW to ReNew Power for two wind projects in India | U20: https://www.siemensgamesa.com/global/en/home/press-releases/india-576-mw-renew-power.html
B21: 24-01-2019 | C21: Brazil | D21: 128 | H21: SG 3.4-132 | I21: 132 | J21: 3.4 | L21: SG 2.1-114 | M21: 114 | N21: 2.1 | P21: Voltalia | R21: 2020 | S21: Siemens Gamesa awarded order for 128 MW for a Voltalia wind project in Rio Grande do Norte, Brazil | U21: https://www.siemensgamesa.com/global/en/home/press-releases/onshore-wind-project-voltalia-rio-grande-do-norte-brazil.html

Sheet 2018
B1: date | C1: country | D1: size [MW] | E1: Service time [years] | F1: customer | G1: # | H1: platform | I1: Rotor | J1: MW | K1: #.1 | L1: platform.1 | M1: Rotor.1 | N1: MW.1 | O1: Tower height | P1: wind farm | Q1: installation q | R1: Installation y | S1: note | T1: owner | U1: link
B2: 11-12-2018 | C2: Russia | D2: 200 | P2: Kola | R2: 2021 | S2: Siemens Gamesa signs second order with Enel in Russia for over 200 MW | U2: https://www.siemensgamesa.com/global/en/home/press-releases/contract-onshore-russia-enel-3-X-platform.html
B3: 10-12-2018 | C3: Mexico | D3: 249 | E3: 5 | H3: SG 4.5-145 | I3: 145 | J3: 4.5 | S3: Siemens Gamesa signs first contract to supply its new wind turbine of the Siemens Gamesa 4.X platform totaling 249 MW in Mexico | U3: https://www.siemensgamesa.com/global/en/home/press-releases/contract-onshore-mexico-enel-4-X-platform.html
B4: 04-12-2018 | C4: Spain | D4: 34.6 | H4: SG 3.4-132 | I4: 132 | J4: 3.4 | P4: Norvento | R4: 2019 | S4: Siemens Gamesa to supply the wind turbines for a Norvento wind farm in Lugo, Spain | U4: https://www.siemensgamesa.com/global/en/home/press-releases/contract-wind-turbines-norvento-lugo-spain.html
B5: 03-12-2018 | C5: Belgium | D5: 487 | E5: 17 | H5: SG 8.0-167 DD | I5: 167 | J5: 8 | L5: SG 8.0-167 | M5: 167 | N5: 8 | P5: Belgium. Project to utilize 58 SG 8.0-167 DD offshore wind turbines | R5: 2020 | S5: Siemens Gamesa to supply 487 MW SeaMade offshore wind power project in Belgium | U5: https://www.siemensgamesa.com/global/en/home/press-releases/contract-offshore-belgium-seamade-8mw-turbines.html
B6: 30-11-2018 | C6: Sweden | D6: 263 | E6: 20 | G6: 34 | P6: Denizly | R6: 2019 | S6: Siemens Gamesa strengthens its presence in the onshore market with new projects totaling 263 MW | U6: https://www.siemensgamesa.com/global/en/home/press-releases/contract-onshore-market-europe-new-projects-totaling-263MW.html
B7: 31-10-2018 | C7: India | D7: 176.8 | H7: SG 2.1-122 | I7: 122 | J7: 2.1 | L7: SG 2.0-114 | M7: 114 | N7: 2 | P7: Osmanabad district | S7: Siemens Gamesa secures 176.8 MW order from ReNew Power for two wind projects in India | U7: https://www.siemensgamesa.com/global/en/home/press-releases/20181031-renew-power-india-two-projects.html
B8: 25-10-2018 | C8: United States | D8: 198.5 | E8: 20 | G8: 484 | H8: SG 3.4-132 | I8: 132 | J8: 3.4 | L8: SWT-2.3-108 | M8: 108 | N8: 2.3 | P8: Reading Wind | S8: Siemens Gamesa awarded order for 198.5 MW wind project in Kansas, USA | U8: https://www.siemensgamesa.com/global/en/home/press-releases/20181025-SGRE-awarded-order-for-wind-project-in-Kansas.html
B9: 05-10-2018 | C9: Russia | D9: 90 | G9: 26 | H9: SG 3.4-132 | I9: 132 | J9: 3.4 | P9: MW Enel | R9: 2020 | S9: Siemens Gamesa enters Russia with its first order for 90 MW Enel wind farm | U9: https://www.siemensgamesa.com/global/en/home/press-releases/20181005-enters-Russia-with-its-first-order-for-90-MW-Enel-wind-farm.html
B10: 03-10-2018 | C10: Taiwan | D10: 120 | H10: SWT-6.0-154 | I10: 154 | J10: 6 | L10: SG 8.0-167 DD | M10: 167 | N10: 8 | P10: Yunlin | R10: 2019 | S10: Siemens Gamesa awards first two contracts for localized offshore wind turbine components in Taiwan | U10: https://www.siemensgamesa.com/global/en/home/press-releases/20181002-SGRE-awards-first-two-contracts-for-localized-offshore-wind-Taiwan.html
B11: 24-09-2018 | C11: Spain | D11: 233 | G11: 20 | H11: SG 3.4-132 | I11: 132 | J11: 3.4 | L11: SG 2.1-114 | M11: 114 | N11: 2.1 | P11: Los Cierzos | S11: Siemens Gamesa continues to win new contracts in Spain: it has been mandated to supply 233 MW at eight wind farms | U11: https://www.siemensgamesa.com/global/en/home/press-releases/20180924-sgre-continues-to-win-new-contracts-in-spain.html
B12: 10-08-2018 | C12: Norway | D12: 208 | G12: 70 | P12: Norway. The | R12: 2019 | S12: Siemens Gamesa to supply wind turbines with 208 MW total capacity for one of Norway’s largest wind park | U12: https://www.siemensgamesa.com/global/en/home/press-releases/2018-10-08-onshore-norway-208-mw.html
B13: 09-08-2018 | C13: United States | D13: 4712 | H13: SWT-6.0-154 | I13: 154 | J13: 6 | P13: Coastal Virginia Offshore Wind | R13: 2020 | S13: Siemens Gamesa and Ørsted sign first U.S. offshore turbine supplier contract | U13: https://www.siemensgamesa.com/global/en/home/press-releases/20180809-offshore-wind-park-usa.html
B14: 03-08-2018 | C14: Netherlands | D14: 380 | G14: 89 | P14: at least 16 years. In the consortium | R14: 2021 | S14: Siemens Gamesa - Van Oord named preferred contractor for Fryslân nearshore wind farm | U14: https://www.siemensgamesa.com/global/en/home/press-releases/Van-Oord-preferred-contractor-030817.html
B15: 11-07-2018 | C15: South Africa | D15: 250 | H15: SWT-2.3-108 | I15: 108 | J15: 2.3 | P15: MW Kangnas | R15: 2018 | S15: Siemens Gamesa to install two large onshore wind farm projects in South Africa | U15: https://www.siemensgamesa.com/global/en/home/press-releases/180711-South-africa-order-two-wind-farm.html
B16: 09-07-2018 | C16: Spain | D16: 289 | E16: 10 | G16: 92 | H16: SG 2.6-114 | I16: 114 | J16: 2.6 | L16: SG 3.4-132 | M16: 132 | N16: 3.4 | P16: El Marquesado | S16: Siemens Gamesa to supply 92 of its newest wind turbine models at 10 wind farms in Spain | U16: https://www.siemensgamesa.com/global/en/home/press-releases/180709-contratos-in-Spain.html
B17: 28-06-2018 | C17: UK | D17: 1386 | G17: 165 | H17: SG 8.0-167 DD | I17: 167 | J17: 8 | L17: SWT-7.0-154 | M17: 154 | N17: 7 | P17: Siemens Gamesa's history | R17: 2022 | S17: Siemens Gamesa will supply the world’s largest offshore project: Ørsted orders 165 turbines for Hornsea Two wind power plant | U17: https://www.siemensgamesa.com/global/en/home/press-releases/siemens-gamesa-news-offshore-hornsea-two-oersted.html
B18: 27-06-2018 | C18: Brazil | D18: 471 | G18: 136 | H18: SG 3.4-132 | I18: 132 | J18: 3.4 | S18: Siemens Gamesa secures Brazil's largest-ever contract: 136 turbines for Iberdrola | U18: https://www.siemensgamesa.com/global/en/home/press-releases/siemens-gamesa-news-brazil-largest-onshore-agreement-iberdrola.html
B19: 26-04-2018 | C19: India | D19: 300 | E19: 10 | G19: 143 | H19: SG 2.1-122 | I19: 122 | J19: 2.1 | P19: India. The | R19: 2019 | S19: Siemens Gamesa secures its largest ever wind turbine order of 300 MW in India | U19: https://www.siemensgamesa.com/global/en/home/press-releases/siemens-gamesa-secures-its-largest-ever-wind-turbine-order-of-300-mw-in-india.html
B20: 25-04-2018 | C20: United States | D20: 508 | P20: King Mountain | S20: Siemens Gamesa seals a 508 MW deal to repower three wind farms in the US | U20: https://www.siemensgamesa.com/global/en/home/press-releases/siemens-gamesa-seals-a-508-mw-deal-to-repower-three-wind-farms-in-the-us.html
B21: 19-04-2018 | C21: India | D21: 140 | H21: SG 2.0-114 | I21: 114 | J21: 2 | R21: 2018 | S21: Siemens Gamesa wins 140 MW of wind power orders in India for multiple projects | U21: https://www.siemensgamesa.com/global/en/home/press-releases/siemens-gamesa-wins-140-mw-of-wind-power-orders-in-india-for-multiple-projects.html
B22: 17-04-2018 | C22: United States | D22: 77 | E22: 5 | H22: SWT-2.625-120 | I22: 120 | J22: 2.625 | L22: SWT-2.3-108 | M22: 108 | N22: 2.3 | P22: MW. The | R22: 2018 | S22: Siemens Gamesa secures 77 MW wind project with MidAmerican Energy in the U.S. | U22: https://www.siemensgamesa.com/global/en/home/press-releases/siemens-gamesa-secures-77-mw-wind-project-with-midamerican-energy-in-the-us.html
B23: 16-04-2018 | C23: Spain | D23: 166 | H23: SG 3.4-132 | I23: 132 | J23: 3.4 | R23: 2019 | S23: Siemens Gamesa to supply 166 MW at four new wind farms to be developed by Gas Natural Fenosa Renovables in Spain | U23: https://www.siemensgamesa.com/global/en/home/press-releases/siemens-gamesa-to-supply-166-mw-at-four-new-wind-farms.html
B24: 10-04-2018 | C24: Australia | D24: 194 | E24: 25 | G24: 56 | H24: SG 3.4-132 | I24: 132 | J24: 3.4 | P24: Australia that will incorporate a battery energy storage system. The company has | R24: 2019 | S24: Siemens Gamesa to build a pioneering 194 MW wind farm in Australia that will incorporate a battery energy storage system | U24: https://www.siemensgamesa.com/global/en/home/press-releases/siemens-gamesa-to-build-a-pioneering-194-mw-wind-farm-in-australia.html
B25: 04-04-2018 | C25: Vietnam | D25: 39 | G25: 12 | H25: SG 2.6-114 | I25: 114 | J25: 2.6 | P25: MW The Dam Nai | R25: 2020 | S25: Siemens Gamesa reinforces its presence in Vietnam with a new order for 39 MW | U25: https://www.siemensgamesa.com/global/en/home/press-releases/siemens-gamesa-reinforces-its-presence-in-vietnam-with-a-new-order-for-39-mw.html
B26: 20-03-2018 | C26: Spain | D26: 18 | H26: SG 2.6-114 | I26: 114 | J26: 2.6 | P26: Iberdrola | S26: Siemens Gamesa boosts its leadership in Spain with the supply of turbines at an Iberdrola wind farm in Tenerife | U26: https://www.siemensgamesa.com/global/en/home/press-releases/siemens-gamesa-boosts-its-leadership-in-spain-with-the-supply-of-turbines-at-an-iberdrola-wind-farm.html
B27: 15-03-2018 | C27: France | D27: 104 | E27: 20 | F27: New | G27: 39 | H27: SWT-3.2-113 | I27: 113 | J27: 3.2 | L27: SG 2.1-114 | M27: 114 | N27: 2.1 | P27: Innovent's Eplessier | Q27: 3 | R27: 2018 | S27: New orders in France: Siemens Gamesa to supply 104 MW for five onshore projects | U27: https://www.siemensgamesa.com/global/en/home/press-releases/new-orders-in-france-siemens-gamesa-to-supply-104-mw-for-five-onshore-projects.html
B28: 02-03-2018 | C28: China | G28: 5 | S28: Siemens Gamesa reinforces offshore strategy in China by licensing the 8 MW Direct Drive technology to partner Shanghai Electric | U28: https://www.siemensgamesa.com/global/en/home/press-releases/siemens-gamesa-reinforces-offshore-strategy-in-china-by-licensing-the-8-mw-direct-drive-technology.html
B29: 27-02-2018 | C29: Turkey | D29: 1000 | E29: 15 | S29: Siemens Gamesa signs an agreement to supply up to 1 GW in Turkey | U29: https://www.siemensgamesa.com/global/en/home/press-releases/siemens-gamesa-signs-an-agreement-to-supply-up-to-1-gw-in-turkey.html
B30: 21-02-2018 | C30: Bosnia and Herzegovina | D30: 36 | G30: 18 | P30: Jelovaca | S30: Siemens Gamesa signs a new contract for the supply of 36 MW in Bosnia and Herzegovina | U30: https://www.siemensgamesa.com/global/en/home/press-releases/siemens-gamesa-signs-a-new-contract-for-the-supply-of-36-mw-in-bosnia-and-herzegovina.html
B31: 22-01-2018 | C31: India | D31: 326 | R31: 2018 | S31: Siemens Gamesa signals turnaround in India winning 326 MW wind power orders from multiple projects with different customers | U31: https://www.siemensgamesa.com/global/en/home/press-releases/siemens-gamesa-signals-turnaround-in-india-winning-326-mw-wind-power-orders-from-multiple-projects.html
B32: 18-01-2018 | D32: 330 | E32: 10 | P32: Midway | R32: 2019 | S32: Siemens Gamesa awarded two wind turbine projects totaling 330 MW of G132-3.465 MW turbines in the U.S. | U32: https://www.siemensgamesa.com/global/en/home/press-releases/siemens-gamesa-awarded-two-wind-turbine-projects-totaling-330-mw-of-g132-3465-mw-turbines-in-the-us.html
B33: 17-01-2018 | C33: China | D33: 96 | P33: Yangshugou | R33: 2018 | S33: Siemens Gamesa continues to grow in China, having signed two new agreements for the supply of 96 MW | U33: https://www.siemensgamesa.com/global/en/home/press-releases/siemens-gamesa-continues-to-grow-in-china-having-signed-two-new-agreements-for-the-supply-of-96-mw.html
B34: 10-01-2018 | C34: France | D34: 500 | H34: SG 8.0-167 DD | I34: 167 | J34: 8 | L34: SWT-7.0-154 | M34: 154 | N34: 7 | P34: MW Saint Brieuc | S34: Siemens Gamesa to supply newest 8 MW direct-drive offshore turbine to 500 MW Saint Brieuc project in France | U34: https://www.siemensgamesa.com/global/en/home/press-releases/siemens-gamesa-to-supply-newest-8-mw-direct-drive-offshore-turbine-to-500-mw.html
B35: 03-01-2018 | C35: Egypt | D35: 262 | E35: 15 | F35: New | P35: Suez | R35: 2026 | S35: New order in Egypt: Siemens Gamesa lands 262 MW turbine supply and 15-year maintenance contract | U35: https://www.siemensgamesa.com/global/en/home/press-releases/new-order-in-egypt-siemens-gamesa-lands-262-mw-turbine-supply-and-15-year-maintenance-contract.html

Sheet 2017
B1: date | C1: country | D1: size [MW] | E1: Service time [years] | F1: customer | G1: # | H1: platform | I1: Rotor | J1: MW | K1: #.1 | L1: platform.1 | M1: Rotor.1 | N1: MW.1 | O1: Tower height | P1: wind farm | Q1: installation q | R1: Installation y | S1: note | T1: owner | U1: link
B2: 28-12-2017 | C2: Italy | D2: 59 | G2: 23 | H2: SWT-3.0-113 | I2: 113 | J2: 3 | P2: Potenza. The | Q2: 3 | R2: 2018 | S2: Two new onshore wind projects in Italian Basilicata region: Siemens Gamesa signs contracts covering 23 turbines | U2: https://www.siemensgamesa.com/global/en/home/press-releases/two-new-onshore-wind-projects-in-italian-basilicata-region-sgre-signs-contracts-covering-23-turbines.html
B3: 20-12-2017 | C3: Spain | D3: 64 | G3: 22 | P3: R&D | Q3: 3 | R3: 2018 | S3: Siemens Gamesa to supply 22 turbines (64 MW) at two wind farms being developed by Gas Natural Fenosa Renovables in Spain | U3: https://www.siemensgamesa.com/global/en/home/press-releases/siemens-gamesa-to-supply-22-turbines-64-mw-at-two-wind-farms.html
B4: 29-11-2017 | C4: India | D4: 200 | P4: Tamil Nadu. This | R4: 2019 | S4: Siemens Gamesa continues to lead the Indian market with a new order for the construction of a 200 MW wind project under a turnkey arrangement | U4: https://www.siemensgamesa.com/global/en/home/press-releases/siemens-gamesa-continues-to-lead-the-indian-market-with-a-new-order-for-the-construction-of-a-200-mw.html
B5: 27-11-2017 | C5: Thailand | D5: 260 | G5: 100 | R5: 2018 | S5: Siemens Gamesa secures its largest-ever order in Thailand where it has been contracted to supply more than 100 turbines with total capacity of 260 MW | U5: https://www.siemensgamesa.com/global/en/home/press-releases/siemens-gamesa-secures-its-largest-ever-order-in-thailand.html
B6: 03-10-2017 | C6: China | D6: 34 | P6: Hubei Energy Lichuan Zhonghao | S6: Siemens Gamesa lands a new contract for the supply of 34 MW in China | U6: https://www.siemensgamesa.com/global/en/home/press-releases/siemens-gamesa-lands-a-new-contract-for-the-supply-of-34-mw-in-china.html
B7: 28-09-2017 | C7: Pakistan | D7: 50 | P7: Zephyr Power | R7: 2018 | S7: Siemens Gamesa debuts in Pakistan: the company wins EPC contract for the supply of 50 MW | U7: https://www.siemensgamesa.com/global/en/home/press-releases/siemens-gamesa-debuts-in-pakistan-the-company-wins-epc-contract-for-the-supply-of-50-mw.html
B8: 26-09-2017 | C8: India | D8: 28.8 | P8: India. It also is the country's first large commercial hybrid project The scope i | S8: Siemens Gamesa wins first order for a hybrid wind-solar project in India | U8: https://www.siemensgamesa.com/global/en/home/press-releases/siemens-gamesa-wins-first-order-for-a-hybrid-wind-solar-project-in-india.html
B9: 20-09-2017 | C9: Argentina | D9: 97 | P9: Argentina. This | Q9: 2 | R9: 2018 | S9: Siemens Gamesa Renewable Energy cements its leadership in Latin America with a 97-MW supply order in Argentina | U9: https://www.siemensgamesa.com/global/en/home/press-releases/sgre-cements-its-leadership-in-latin-america-with-a-97-mw-supply-order-in-argentina.html
B10: 17-09-2017 | C10: China | D10: 300 | P10: Inner Mongolia The | Q10: 2 | R10: 2018 | S10: Siemens Gamesa reinforces its presence in China with a new order for 300 MW, one of its largest ever in this market | U10: https://www.siemensgamesa.com/global/en/home/press-releases/siemens-gamesa-reinforces-its-presence-in-china-with-a-new-order-for-300-mw.html
B11: 24-07-2017 | C11: Mexico | D11: 76 | G11: 36 | R11: 2018 | S11: Siemens Gamesa to supply 36 turbines in Mexico | U11: https://www.siemensgamesa.com/global/en/home/press-releases/siemens-gamesa-to-supply-36-turbines-in-mexico.html
B12: 14-07-2017 | C12: Turkey | D12: 118 | G12: 36 | P12: Baglar | Q12: 2 | R12: 2018 | S12: Siemens Gamesa to supply 118 MW in Turkey, marking the début order in Europe for its new 3.3 MW platform | U12: https://www.siemensgamesa.com/global/en/home/press-releases/siemens-gamesa-to-supply-118-mw-in-turkey-marking-the-debut-order-in-europe.html

Sheet projections
C1: wolrd market
C2: installation pr year | E2: data from annaul report 2022 - activity report
C3: On and Offshore
E5: est | F5: est | G5: est | H5: est | I5: est | J5: est | K5: est | L5: est | M5: est
D6: 2021 | E6: 2022 | F6: 2023 | G6: 2024 | H6: 2025 | I6: 2026 | J6: 2027 | K6: 2028 | L6: 2029 | M6: 2030
C7: total | D7: =SUM(D8:D10) -> 94 | E7: =SUM(E8:E10) -> 95 | F7: =SUM(F8:F10) -> 112 | G7: =SUM(G8:G10) -> 121 | H7: =SUM(H8:H10) -> 139 | I7: =SUM(I8:I10) -> 134 | J7: =SUM(J8:J10) -> 141 | K7: =SUM(K8:K10) -> 146 | ... M7: =SUM(M8:M10) -> 168
C8: Rest of world | D8: 33 | E8: 34 | F8: 43 | G8: 44 | H8: 54 | I8: 50 | J8: 57 | K8: 62 | L8: 72 | M8: 78
C9: NA | D9: 13 | E9: 13 | F9: 10 | G9: 10 | H9: 13 | I9: 16 | J9: 16 | K9: 17 | L9: 19 | M9: 18
C10: China | D10: 48 | E10: 48 | F10: 59 | G10: 67 | H10: 72 | I10: 68 | J10: 68 | K10: 67 | L10: 70 | M10: 72
C13: offshore
C14: RoW | E14: =0.1*E8 -> 3.4 | F14: =0.15*F8 -> 6.45 | G14: =0.2*G8 -> 8.8 | H14: =0.25*H8 -> 13.5 | I14: =0.3*I8 -> 15 | J14: =0.35*J8 -> 19.95 | K14: =0.39*K8 -> 24.18 | L14: =0.42*L8 -> 30.24 | M14: =0.45*M8 -> 35.1
C15: China | E15: =0.16*E10 -> 7.68 | F15: =0.17*F10 -> 10.03 | G15: =0.18*G10 -> 12.06 | H15: =0.2*H10 -> 14.4 | I15: =0.22*I10 -> 14.96 | J15: =0.23*J10 -> 15.64 | K15: =0.24*K10 -> 16.08 | L15: =0.26*L10 -> 18.2 | M15: =0.27*M10 -> 19.44

Sheet plots
C4: region | D4: 2022 | E4: 2021 | F4: 2020
C5: AF | E5: ='2021'!G36 -> 0 | F5: ='2020'!F35 -> 0
C6: AS | D6: ='2022'!G33 -> 0 | E6: ='2021'!G39 -> 0 | F6: ='2020'!F38 -> 0
C7: AU | E7: ='2021'!G40 -> 0
C8: EU | D8: ='2022'!G41 -> 0 | E8: ='2021'!G49 -> 0 | F8: ='2020'!F42 -> 0
C9: NA | E9: ='2021'!G51 -> 0 | F9: ='2020'!F44 -> 0
C10: SA | E10: ='2021'!G53 -> 0 | F10: ='2020'!F46 -> 0

Sheet delivery 2023
B1: contract date | C1: country | D1: size [MW] | E1: Service time [years] | F1: customer | G1: # | H1: platform | I1: Rotor | J1: MW | K1: # | L1: platform | M1: Rotor | N1: MW | O1: Tower height | P1: wind farm | Q1: installation q | R1: Installation y | T1: note | V1: owner | X1: link
B2: 44785 | C2: India | D2: 345.6 | F2: Azure Power india | G2: 96 | H2: SG 3.6-145 | I2: 145 | J2: 3.6 | Q2: 2 | R2: 2023 | X2: https://www.siemensgamesa.com/newsroom/2022/08/081122-siemens-gamesa-press-release-azure-india-onshore-project
B3: 44771 | C3: Japan | D3: 113 | E3: 15 | G3: 14 | H3: SG 8.0-167 | I3: 167 | J3: 8 | P3: Ishikari | Q3: 3 | R3: 2023 | X3: https://www.siemensgamesa.com/newsroom/2022/07/072922-siemens-gamesa-press-release-first-offshore-project-ishikari-japan
B4: 44722 | C4: India | D4: 133 | G4: 37 | H4: SG 3.6-145 | I4: 145 | J4: 3.6 | R4: 2023 | X4: https://www.siemensgamesa.com/newsroom/2022/06/061022-siemens-gamesa-press-release-vena-energy-india-133mw
B5: 44711 | C5: Spain | D5: 110 | E5: 25 | F5: Greenalia | G5: 22 | H5: SG 5.0-145 | I5: 145 | J5: 5 | Q5: 4 | R5: 2023 | X5: https://www.siemensgamesa.com/newsroom/2022/05/053022-siemens-gamesa-press-release-greenalia-campelos-spain-110mw
B6: 44579 | C6: Spain | D6: 64 | E6: 5 | F6: Iberdrola | G6: 14 | H6: SG 6.6-170 | I6: 170 | J6: 6.6 | K6: 2 | L6: SG 5.0-145 | R6: 2023 | X6: https://www.siemensgamesa.com/newsroom/2022/01/220118-siemens-gamesa-press-release-siemens-gamesa-press-release-iberdrola-spain-5x-onshore
B7: 44560 | C7: Sweden | D7: 260 | E7: 25 | F7: Eolus | G7: 42 | H7: SG 6.6-170 | I7: 170 | J7: 6.6 | O7: 115-123 | P7: Stor-Skälsjön | R7: 2023 | X7: https://www.siemensgamesa.com/newsroom/2021/12/211230-siemens-gamesa-press-release-deal-eolus-hydro-rein-sweden-5x
B8: 44557 | C8: India | D8: 302 | F8: NIIF | G8: 84 | H8: SG 3.6-145 | I8: 145 | J8: 3.6 | R8: 2023 | X8: https://www.siemensgamesa.com/newsroom/2021/12/211227-siemens-gamesa-press-release-3-x-platfomr-ayana-renewable-power-india
B9: 44545 | C9: Denmark | D9: 344 | E9: 3 | F9: Vattenfall | G9: 41 | H9: SG 8.0-167 DD | I9: 167 | J9: 8 | P9: Vestashav Nord + Syd | R9: 2023 | X9: https://www.siemensgamesa.com/newsroom/2021/12/211215-siemens-gamesa-press-release-vesterhav-projects-firm-order
B10: 44299 | C10: Peru | D10: 260 | G10: 50 | H10: SG 5.0-145 | I10: 145 | J10: =D10/G10 -> 5.2 | Q10: 1 | R10: 2023 | X10: https://www.siemensgamesa.com/newsroom/2021/04/210413-siemens-gamesa-press-release-peru-punta-lomitas
B11: 44286 | C11: UK | D11: 1400 | F11: RWE | G11: 100 | H11: SG 14-222 DD | I11: 222 | J11: 14 | P11: Sofia | R11: 2023 | T11: 195 km offshore, 35 m water depth | X11: https://www.siemensgamesa.com/newsroom/2021/03/210330-siemens-gamesa-press-release-sofia-uk
B12: 44200 | C12: Ethiopia | D12: 100 | F12: EEP | G12: 29 | H12: SG 3.4-132 | I12: 132 | J12: 3.4 | Q12: 2 | R12: 2023 | X12: https://www.siemensgamesa.com/newsroom/2021/01/210104-siemens-gamesa-press-release-first-wind-farm-ethiopia-en
B13: 44104 | C13: Sweden | D13: 68.4 | E13: 15 | F13: Eolus Vind | G13: 7 | H13: SG 5.8-170 | I13: 170 | J13: 5.8 | K13: 4 | L13: SG 5.8-155 | M13: 155 | N13: 5.8 | R13: 2023 | X13: https://www.siemensgamesa.com/newsroom/2020/09/200930-siemens-gamesa-press-release-sweden-5x-eolus-vind
B14: 43980 | C14: France | D14: 496 | E14: 10 | F14: Iberdrola | G14: 62 | H14: SG 8.0-167 DD | I14: 167 | J14: 8 | P14: Bay of Saint Brieuc | R14: 2023 | X14: https://www.siemensgamesa.com/newsroom/2020/05/200529-siemens-gamesa-bay-of-saint-brieuc-offshore
A15: =SUM(D2:D14) -> 3996
B21: region | C21: country | D21: size [MW]
B22: AF | C22: Ethiopia | D22: =SUMIF(C$2:C$21,C22,D$2:D$21) -> 100
B23: AS | C23: India | D23: =SUMIF(C$2:C$21,C23,D$2:D$21) -> 780.6
B24: AS | C24: Japan | D24: =SUMIF(C$2:C$21,C24,D$2:D$21) -> 113
B25: EU | C25: Denmark | D25: =SUMIF(C$2:C$21,C25,D$2:D$21) -> 344 | F25: =SQRT(D25)/8 -> 2.3184046
B26: EU | C26: France | D26: =SUMIF(C$2:C$21,C26,D$2:D$21) -> 496 | F26: =SQRT(D26)/8 -> 2.7838822
B27: EU | C27: Spain | D27: =SUMIF(C$2:C$21,C27,D$2:D$21) -> 174 | F27: =SQRT(D27)/8 -> 1.6488632
B28: EU | C28: Sweden | D28: =SUMIF(C$2:C$21,C28,D$2:D$21) -> 328.4 | F28: =SQRT(D28)/8 -> 2.2652263
B29: EU | C29: UK | D29: =SUMIF(C$2:C$21,C29,D$2:D$21) -> 1400 | F29: =SQRT(D29)/8 -> 4.6770717
B30: SA | C30: Peru | D30: =SUMIF(C$2:C$21,C30,D$2:D$21) -> 260

Sheet delivery 2024
B1: contract date | C1: country | D1: size [MW] | E1: Service time [years] | F1: customer | G1: # | H1: platform | I1: Rotor | J1: MW | K1: # | L1: platform | M1: Rotor | N1: MW | O1: Tower height | P1: wind farm | Q1: installation q | R1: Installation y | T1: note | V1: owner | X1: link
B2: 44550 | C2: Germany | D2: 242 | E2: 5 | F2: Ørsted | G2: 23 | H2: SG 11.0-200 DD | I2: 200 | J2: 11 | P2: Gode Wind 3 | R2: 2024 | X2: https://www.siemensgamesa.com/newsroom/2021/12/siemens-gamesa-press-release-offshore-gode-wind-3-firm-order
B3: 44524 | C3: Finland | D3: 455 | E3: 35 | F3: OX2 | G3: 69 | H3: SG 6.6-170 | I3: 170 | J3: 6.6 | P3: Lestijärvi | R3: 2024 | X3: https://www.siemensgamesa.com/newsroom/2021/11/211124-siemens-gamesa-press-release-finland-lestijarvvi-455mw
B4: 44412 | C4: Sweden | D4: 242 | E4: 30 | F4: Arise | G4: 39 | H4: SG 5.8-170 | P4: Ranasjö + Salsjö | Q4: 1 | R4: 2024 | X4: https://www.siemensgamesa.com/newsroom/2021/08/210804-siemens-gamesa-press-release-sweden-twin-peaks
B5: 44854 | C5: Finland | D5: 105 | E5: 35 | F5: Energiequelle | G5: 16 | H5: SG 6.6-170 | I5: 170 | J5: 6.6 | O5: 145 | Q5: 2 | R5: 2024 | X5: https://www.siemensgamesa.com/newsroom/2022/10/102022-siemens-gamesa-press-release-onshore-finland-mikonkeidas-energiequelle
